"Id","CaseNumber","Ticket_Record_Type_Name__c","Subject","Description","DevOps_Steps_to_Reproduce__c","What_We_Know__c","Next_Steps__c","Solution_Comment__c","Issue_Type__c","Ticket_Owner_Name__c","Ticket_Type__c","Platform__c","Collector_Code__c","Feature__c","Product_Version__c","Build_Number__c","Age__c","Status","Account_Name__c","Contact_Name__c","CreatedDate","ClosedDate"
"500Qk00000JplLVIAZ","00430599","Support Ticket","New Job crashes","I created a new job group. As of now I am pointing to a host group with one host. The Permissions job crashes. Activity and SDD jobs run fine. I also want to note that the Servers guys changed IP in the middle of the first time I was running the activity job. Not sure if they caused some remnants to be left behind.

This is the error Activity is throing:
System.IndexOutOfRangeException: There is no row at position 0.
   at <a href='https://Stealthbits.StealthAUDIT.DataCollectors.FSAA.Util' target='_blank'>Stealthbits.StealthAUDIT.DataCollectors.FSAA.Util</a>.RunInBackground[TResult](Action statusAction, Func`1 execAction)
   at <a href='https://Stealthbits.StealthAUDIT.DataCollectors.FSAA.Util' target='_blank'>Stealthbits.StealthAUDIT.DataCollectors.FSAA.Util</a>.RunTaskInBackground[TResult](Func`1 statusTask, Func`1 execTask)
   at <a href='https://Stealthbits.StealthAUDIT.DataCollectors.FSAA.Util' target='_blank'>Stealthbits.StealthAUDIT.DataCollectors.FSAA.Util</a>.RunTaskInBackground(Func`1 statusTask, Func`1 execTask)
   at <a href='https://Stealthbits.StealthAUDIT.DataCollectors.FSAA' target='_blank'>Stealthbits.StealthAUDIT.DataCollectors.FSAA</a>.AccessScanTask.d__2.MoveNext()
--- End of stack trace from previous location where exception was thrown ---
   at System.Runtime.ExceptionServices.ExceptionDispatchInfo.Throw()
   at <a href='https://Stealthbits.StealthAUDIT.DataCollectors.FSAA' target='_blank'>Stealthbits.StealthAUDIT.DataCollectors.FSAA</a>.AccessScanTask.d__2.MoveNext()
--- End of stack trace from previous location where exception was thrown ---
   at System.Runtime.CompilerServices.TaskAwaiter.ThrowForNonSuccess(Task task)
   at System.Runtime.CompilerServices.TaskAwaiter.HandleNonSuccessAndDebuggerNotification(Task task)
   at <a href='https://Stealthbits.StealthAUDIT.DataCollectors.FSAA' target='_blank'>Stealthbits.StealthAUDIT.DataCollectors.FSAA</a>.AccessScanTask.InternalProcessRecord()
   at <a href='https://Stealthbits.StealthAUDIT.DataCollectors.Tasks.Task' target='_blank'>Stealthbits.StealthAUDIT.DataCollectors.Tasks.Task</a>.StartExecute()","","this has been resolved and closed but the client emailed on, and reopened, this ticket by mistake. He then emailed on the correct ticket

closing this again","","The target FS's IP address was changed mid scan

determined the issue was likely due to corrupted T2s on the proxy server, and successfully remediated the issue.

We resolved the issue by renaming the old T2 folder for the problematic server (effectively deleting them) then dropping the data from the database

we ran a shallow test scan to confirm the issue was resolved then performed a full scan.

The FS is small and successfully completed while on the call","Advanced Configuration Change","Joshua Sexton","Error","Netwrix Enterprise Auditor","StealthAUDIT for Windows File Systems","Access Auditing","11.6","","11.0","Closed - Resolved","WellSpan Health","John Masgalas","2024-12-23T15:56:32.000Z","2025-01-03T14:52:41.000Z"
