"Id","ParentId","Type","CreatedById","CreatedDate","Body","Title","LinkUrl","RelatedRecordId","InsertedById","LastModifiedDate"
"0D5Qk00000TZLW2KAP","500Qk00000JplLVIAZ","TextPost","0054u000008ARZjAAO","2024-12-23T15:56:33.000Z","Description: I created a new job group. As of now I am pointing to a host group with one host. The Permissions job crashes. Activity and SDD jobs run fine. I also want to note that the Servers guys changed IP in the middle of the first time I was running the activity job. Not sure if they caused some remnants to be left behind.

This is the error Activity is throing:
System.IndexOutOfRangeException: There is no row at position 0.
   at <a href='https://Stealthbits.StealthAUDIT.DataCollectors.FSAA.Util' target='_blank'>Stealthbits.StealthAUDIT.DataCollectors.FSAA.Util</a>.RunInBackground[TResult](Action statusAction, Func`1 execAction)
   at <a href='https://Stealthbits.StealthAUDIT.DataCollectors.FSAA.Util' target='_blank'>Stealthbits.StealthAUDIT.DataCollectors.FSAA.Util</a>.RunTaskInBackground[TResult](Func`1 statusTask, Func`1 execTask)
   at <a href='https://Stealthbits.StealthAUDIT.DataCollectors.FSAA.Util' target='_blank'>Stealthbits.StealthAUDIT.DataCollectors.FSAA.Util</a>.RunTaskInBackground(Func`1 statusTask, Func`1 execTask)
   at <a href='https://Stealthbits.StealthAUDIT.DataCollectors.FSAA' target='_blank'>Stealthbits.StealthAUDIT.DataCollectors.FSAA</a>.AccessScanTask.d__2.MoveNext()
--- End of stack trace from previous location where exception was thrown ---
   at System.Runtime.ExceptionServices.ExceptionDispatchInfo.Throw()
   at <a href='https://Stealthbits.StealthAUDIT.DataCollectors.FSAA' target='_blank'>Stealthbits.StealthAUDIT.DataCollectors.FSAA</a>.AccessScanTask.d__2.MoveNext()
--- End of stack trace from previous location where exception was thrown ---
   at System.Runtime.CompilerServices.TaskAwaiter.ThrowForNonSuccess(Task task)
   at System.Runtime.CompilerServices.TaskAwaiter.HandleNonSuccessAndDebuggerNotification(Task task)
   at <a href='https://Stealthbits.StealthAUDIT.DataCollectors.FSAA' target='_blank'>Stealthbits.StealthAUDIT.DataCollectors.FSAA</a>.AccessScanTask.InternalProcessRecord()
   at <a href='https://Stealthbits.StealthAUDIT.DataCollectors.Tasks.Task' target='_blank'>Stealthbits.StealthAUDIT.DataCollectors.Tasks.Task</a>.StartExecute()","","","","0054u000008ARZjAAO","2024-12-23T15:56:33.000Z"
"0D5Qk00000U98dVKAR","500Qk00000JplLVIAZ","TextPost","0054u000007oss5AAA","2025-01-02T19:29:11.000Z","<p>zoom meeting</p><p> </p><p>they have another domain</p><p>have a trust</p><p>wanted to start monitoring their file servers</p><p> </p><p>they think all ports are open</p><p> </p><p>windows server</p><p> </p><p>ablet o push agent via NAM</p><p>NAM is periodically throwing &quot;unable to contact agent, check port 4449?</p><p>NAM agent is getting events</p><p>-this is likely just a UI issue</p><p>-fixed in newer build</p><p> </p><p>UNC from proxy to FS worked</p><p> </p><p>renaming T2 folder on proxy</p><p>dropping data from tables for that FS</p><p> </p><p>running the job again at 1 level deep</p><p>seemed to work</p><p>bulk import is running</p><p> </p><p> finished and looks good</p><p> </p><p>changing scan back to full depth</p><p>-small FS - test server</p><p> </p><p> </p><p> </p><p> </p><p> </p><p> </p>","","","","0054u000007oss5AAA","2025-01-02T19:29:11.000Z"
"0D5Qk00000UBistKAD","500Qk00000JplLVIAZ","TextPost","0054u000007oss5AAA","2025-01-03T14:52:26.000Z","What We've Learned Updated: this has been resolved and closed but the client emailed on, and reopened, this ticket by mistake. He then emailed on the correct ticket

closing this again","","","","0054u000007oss5AAA","2025-01-03T14:52:26.000Z"
